Workbook

Sheet CLIENTES
A1: N° GRUPO | B1: GRUPO | C1: N° EMPRESA | D1: EMPRESA | E1: NOMBRE FANTASÍA INTERNO AYB | F1: RUT EMPRESA | H1: REPRESENTANTES LEGALES | I1: SOCIOS | J1: TIPO DE SERVICIO | K1: PERIODICIDAD SERVICIO | L1: DETALLE SERVICIO | M1: ACTIVIDADES ASOCIADAS AL SERVICIO | N1: COMPLEJIDAD CLIENTE | O1: EJECUTIVO CONTABLE A CARGO | P1: CORREO CONTACTO EJECUTIVO CONTABLE | Q1: CORREO CONTACTO SII | R1: CORREO NOTIFICACIÓN SII | S1: INFORMACIÓN A RECIBIR DESDE EL CLIENTE | T1: INFORMACIÓN A ENTREGAR AL CLIENTE | U1: VIGENCIA BD AYB
A2: 1 | B2: GRUPO ABCIA | C2: 1 | D2: RENTAS LEXCORP LIMITADA | E2: RENTAS LEXCORP | F2: 78952550-1 | G2: =D2 -> RENTAS LEXCORP LIMITADA | H2: =COUNTIFS(RELACIONADAS!$C:$C,CLIENTES!$F2,RELACIONADAS!$G:$G,"SI") -> 1 | I2: =COUNTIFS(RELACIONADAS!$C:$C,CLIENTES!$F2,RELACIONADAS!$H:$H,"SI") -> 3 | J2: CONTABLE | K2: PERMANENTE | L2: NA | M2: Matriz_Actividades-Tareas_AyB.xlsx | N2: BAJA | O2: ANA MARÍA ACEVEDO | P2: anamaria.acevedo@araybustamante.cl | Q2: anamaria.acevedo@araybustamante.cl | R2: carlos.arag@araybustamante.cl | S2: * CARTOLAS BANCARIAS * CARTOLAS DE INVERSIÓN * LIBRO BANCO * FACTURAS (COMPRAS Y VENTAS DE INVERSIONES) * OPCIONALES: CONTRATOS DE ARRIENDOS, PAGARÉS, ENTRE OTROS | T2: * FORMULARIO 29 * AVISO DE PATENTES COMERCIALES (SEMESTRAL) * FORMULARIO 22 (PERSONA) * FORMULARIO 22 | U2: 45869
A3: 1 | B3: GRUPO ABCIA | C3: 2 | D3: SOCIEDAS CIVIL DE RENTAS LA PASTORA S.C | E3: RENTAS LA PASTORA | F3: 76082746-0 | G3: =D3 -> SOCIEDAS CIVIL DE RENTAS LA PASTORA S.C | H3: =COUNTIFS(RELACIONADAS!$C:$C,CLIENTES!$F3,RELACIONADAS!$G:$G,"SI") -> 2 | I3: =COUNTIFS(RELACIONADAS!$C:$C,CLIENTES!$F3,RELACIONADAS!$H:$H,"SI") -> 6 | J3: CONTABLE | K3: PERMANENTE | L3: NA | M3: Matriz_Actividades-Tareas_AyB.xlsx | N3: BAJA | O3: ANA MARÍA ACEVEDO | P3: anamaria.acevedo@araybustamante.cl | Q3: anamaria.acevedo@araybustamante.cl | R3: carlos.arag@araybustamante.cl | S3: * CARTOLAS BANCARIAS * CARTOLAS DE INVERSIÓN * LIBRO BANCO * FACTURAS (COMPRAS Y VENTAS DE INVERSIONES) * OPCIONALES: CONTRATOS DE ARRIENDOS, PAGARÉS, ENTRE OTROS | T3: * FORMULARIO 29 * AVISO DE PATENTES COMERCIALES (SEMESTRAL) * FORMULARIO 22 (PERSONA) * FORMULARIO 22 | U3: 45869
A4: 1 | B4: GRUPO ABCIA | C4: 3 | D4: INVERSIONES RODAS DE BAHIA LIMITADA | E4: RODAS DE BAHÍA | F4: 79978870-5 | G4: =D4 -> INVERSIONES RODAS DE BAHIA LIMITADA | H4: =COUNTIFS(RELACIONADAS!$C:$C,CLIENTES!$F4,RELACIONADAS!$G:$G,"SI") -> 1 | I4: =COUNTIFS(RELACIONADAS!$C:$C,CLIENTES!$F4,RELACIONADAS!$H:$H,"SI") -> 8 | J4: CONTABLE | K4: PERMANENTE | L4: NA | M4: Matriz_Actividades-Tareas_AyB.xlsx | N4: ALTA | O4: ANA MARÍA ACEVEDO | P4: anamaria.acevedo@araybustamante.cl | Q4: anamaria.acevedo@araybustamante.cl | R4: carlos.arag@araybustamante.cl | S4: * CARTOLAS BANCARIAS * CARTOLAS DE INVERSIÓN * LIBRO BANCO * FACTURAS (COMPRAS Y VENTAS DE INVERSIONES) * OPCIONALES: CONTRATOS DE ARRIENDOS, PAGARÉS, ENTRE OTROS | T4: * FORMULARIO 29 * AVISO DE PATENTES COMERCIALES (SEMESTRAL) * FORMULARIO 22 (PERSONA) * FORMULARIO 22 | U4: 45869
A5: 1 | B5: GRUPO ABCIA | C5: 4 | D5: RENTAS LA LLAVERIA LIMITADA | E5: RENTAS LA LLAVERÍA | F5: 76007540-k | G5: =D5 -> RENTAS LA LLAVERIA LIMITADA | H5: =COUNTIFS(RELACIONADAS!$C:$C,CLIENTES!$F5,RELACIONADAS!$G:$G,"SI") -> 2 | I5: =COUNTIFS(RELACIONADAS!$C:$C,CLIENTES!$F5,RELACIONADAS!$H:$H,"SI") -> 2 | J5: CONTABLE | K5: PERMANENTE | L5: NA | M5: Matriz_Actividades-Tareas_AyB.xlsx | N5: ALTA | O5: ANA MARÍA ACEVEDO | P5: anamaria.acevedo@araybustamante.cl | Q5: anamaria.acevedo@araybustamante.cl | R5: carlos.arag@araybustamante.cl | S5: * CARTOLAS BANCARIAS * CARTOLAS DE INVERSIÓN * LIBRO BANCO * FACTURAS (COMPRAS Y VENTAS DE INVERSIONES) * OPCIONALES: CONTRATOS DE ARRIENDOS, PAGARÉS, ENTRE OTROS | T5: * FORMULARIO 29 * AVISO DE PATENTES COMERCIALES (SEMESTRAL) * FORMULARIO 22 (PERSONA) * FORMULARIO 22 | U5: 45869
A6: 1 | B6: GRUPO ABCIA | C6: 5 | D6: RENTAS ALPER LIMITADA | E6: RENTAS ALPER | F6: 53317631-3 | G6: =D6 -> RENTAS ALPER LIMITADA | H6: =COUNTIFS(RELACIONADAS!$C:$C,CLIENTES!$F6,RELACIONADAS!$G:$G,"SI") -> 2 | I6: =COUNTIFS(RELACIONADAS!$C:$C,CLIENTES!$F6,RELACIONADAS!$H:$H,"SI") -> 7 | J6: CONTABLE | K6: PERMANENTE | L6: NA | M6: Matriz_Actividades-Tareas_AyB.xlsx | N6: BAJA | O6: ANA MARÍA ACEVEDO | P6: anamaria.acevedo@araybustamante.cl | Q6: anamaria.acevedo@araybustamante.cl | R6: carlos.arag@araybustamante.cl | S6: * CARTOLAS BANCARIAS * CARTOLAS DE INVERSIÓN * LIBRO BANCO * FACTURAS (COMPRAS Y VENTAS DE INVERSIONES) * OPCIONALES: CONTRATOS DE ARRIENDOS, PAGARÉS, ENTRE OTROS | T6: * FORMULARIO 29 * AVISO DE PATENTES COMERCIALES (SEMESTRAL) * FORMULARIO 22 (PERSONA) * FORMULARIO 22 | U6: 45869
A7: 1 | B7: GRUPO ABCIA | C7: 6 | D7: SOCIEDAD CIVIL DE RENTAS EL ARCON S.C | E7: RENTAS EL ARCÓN | F7: 77989350-2 | G7: =D7 -> SOCIEDAD CIVIL DE RENTAS EL ARCON S.C | H7: =COUNTIFS(RELACIONADAS!$C:$C,CLIENTES!$F7,RELACIONADAS!$G:$G,"SI") -> 1 | I7: =COUNTIFS(RELACIONADAS!$C:$C,CLIENTES!$F7,RELACIONADAS!$H:$H,"SI") -> 3 | J7: CONTABLE | K7: PERMANENTE | L7: NA | M7: Matriz_Actividades-Tareas_AyB.xlsx | N7: BAJA | O7: ANA MARÍA ACEVEDO | P7: anamaria.acevedo@araybustamante.cl | Q7: anamaria.acevedo@araybustamante.cl | R7: carlos.arag@araybustamante.cl | S7: * CARTOLAS BANCARIAS * CARTOLAS DE INVERSIÓN * LIBRO BANCO * FACTURAS (COMPRAS Y VENTAS DE INVERSIONES) * OPCIONALES: CONTRATOS DE ARRIENDOS, PAGARÉS, ENTRE OTROS | T7: * FORMULARIO 29 * AVISO DE PATENTES COMERCIALES (SEMESTRAL) * FORMULARIO 22 (PERSONA) * FORMULARIO 22 | U7: 45869
A8: 1 | B8: GRUPO ABCIA | C8: 7 | D8: RENTAS E INVERSIONES MONTREAL LIMITADA | E8: RENTAS MONTREAL | F8: 76452272-9 | G8: =D8 -> RENTAS E INVERSIONES MONTREAL LIMITADA | H8: =COUNTIFS(RELACIONADAS!$C:$C,CLIENTES!$F8,RELACIONADAS!$G:$G,"SI") -> 2 | I8: =COUNTIFS(RELACIONADAS!$C:$C,CLIENTES!$F8,RELACIONADAS!$H:$H,"SI") -> 2 | J8: CONTABLE | K8: PERMANENTE | L8: NA | M8: Matriz_Actividades-Tareas_AyB.xlsx | N8: BAJA | O8: ANA MARÍA ACEVEDO | P8: anamaria.acevedo@araybustamante.cl | Q8: anamaria.acevedo@araybustamante.cl | R8: carlos.arag@araybustamante.cl | S8: * CARTOLAS BANCARIAS * CARTOLAS DE INVERSIÓN * LIBRO BANCO * FACTURAS (COMPRAS Y VENTAS DE INVERSIONES) * OPCIONALES: CONTRATOS DE ARRIENDOS, PAGARÉS, ENTRE OTROS | T8: * FORMULARIO 29 * AVISO DE PATENTES COMERCIALES (SEMESTRAL) * FORMULARIO 22 (PERSONA) * FORMULARIO 22 | U8: 45869
A9: 1 | B9: GRUPO ABCIA | C9: 8 | D9: SOCIEDAD CIVIL DE RENTAS CADINI S.C | E9: RENTAS CADINI | F9: 76082218-3 | G9: =D9 -> SOCIEDAD CIVIL DE RENTAS CADINI S.C | H9: =COUNTIFS(RELACIONADAS!$C:$C,CLIENTES!$F9,RELACIONADAS!$G:$G,"SI") -> 2 | I9: =COUNTIFS(RELACIONADAS!$C:$C,CLIENTES!$F9,RELACIONADAS!$H:$H,"SI") -> 5 | J9: CONTABLE | K9: PERMANENTE | L9: NA | M9: Matriz_Actividades-Tareas_AyB.xlsx | N9: BAJA | O9: ANA MARÍA ACEVEDO | P9: anamaria.acevedo@araybustamante.cl | Q9: anamaria.acevedo@araybustamante.cl | R9: carlos.arag@araybustamante.cl | S9: * CARTOLAS BANCARIAS * CARTOLAS DE INVERSIÓN * LIBRO BANCO * FACTURAS (COMPRAS Y VENTAS DE INVERSIONES) * OPCIONALES: CONTRATOS DE ARRIENDOS, PAGARÉS, ENTRE OTROS | T9: * FORMULARIO 29 * AVISO DE PATENTES COMERCIALES (SEMESTRAL) * FORMULARIO 22 (PERSONA) * FORMULARIO 22 | U9: 45869
A10: 1 | B10: GRUPO ABCIA | C10: 9 | D10: INMOBILIARIA ESPACIO LEGAL SPA | E10: ESPACIO LEGAL | F10: 76871245-K | G10: =D10 -> INMOBILIARIA ESPACIO LEGAL SPA | H10: =COUNTIFS(RELACIONADAS!$C:$C,CLIENTES!$F10,RELACIONADAS!$G:$G,"SI") -> 5 | I10: =COUNTIFS(RELACIONADAS!$C:$C,CLIENTES!$F10,RELACIONADAS!$H:$H,"SI") -> 3 | J10: CONTABLE | K10: PERMANENTE | L10: NA | M10: Matriz_Actividades-Tareas_AyB.xlsx | N10: MEDIA | O10: ANA MARÍA ACEVEDO | P10: anamaria.acevedo@araybustamante.cl | Q10: anamaria.acevedo@araybustamante.cl | R10: carlos.arag@araybustamante.cl | S10: * CARTOLAS BANCARIAS * CARTOLAS DE INVERSIÓN * LIBRO BANCO * FACTURAS (COMPRAS Y VENTAS DE INVERSIONES) * OPCIONALES: CONTRATOS DE ARRIENDOS, PAGARÉS, ENTRE OTROS | T10: * FORMULARIO 29 * AVISO DE PATENTES COMERCIALES (SEMESTRAL) * FORMULARIO 22 (PERSONA) * FORMULARIO 22 | U10: 45869
A11: 1 | B11: GRUPO ABCIA | C11: 10 | D11: RENTAS ABCIA LIMITADA | E11: RENTAS ABCIA | F11: 76548690-4 | G11: =D11 -> RENTAS ABCIA LIMITADA | H11: =COUNTIFS(RELACIONADAS!$C:$C,CLIENTES!$F11,RELACIONADAS!$G:$G,"SI") -> 3 | I11: =COUNTIFS(RELACIONADAS!$C:$C,CLIENTES!$F11,RELACIONADAS!$H:$H,"SI") -> 3 | J11: CONTABLE | K11: PERMANENTE | L11: NA | M11: Matriz_Actividades-Tareas_AyB.xlsx | N11: BAJA | O11: ANA MARÍA ACEVEDO | P11: anamaria.acevedo@araybustamante.cl | Q11: anamaria.acevedo@araybustamante.cl | R11: carlos.arag@araybustamante.cl | S11: * CARTOLAS BANCARIAS * CARTOLAS DE INVERSIÓN * LIBRO BANCO * FACTURAS (COMPRAS Y VENTAS DE INVERSIONES) * OPCIONALES: CONTRATOS DE ARRIENDOS, PAGARÉS, ENTRE OTROS | T11: * FORMULARIO 29 * AVISO DE PATENTES COMERCIALES (SEMESTRAL) * FORMULARIO 22 (PERSONA) * FORMULARIO 22 | U11: 45869
A12: 1 | B12: GRUPO ABCIA | C12: 11 | D12: INVERSIONES RODAS DE BAHIA INTERNACIONAL SPA | E12: RODAS DE BAHÍA INTERNACIONAL | F12: 78036432-7 | G12: =D12 -> INVERSIONES RODAS DE BAHIA INTERNACIONAL SPA | H12: =COUNTIFS(RELACIONADAS!$C:$C,CLIENTES!$F12,RELACIONADAS!$G:$G,"SI") -> 2 | I12: =COUNTIFS(RELACIONADAS!$C:$C,CLIENTES!$F12,RELACIONADAS!$H:$H,"SI") -> 1 | J12: CONTABLE | K12: PERMANENTE | L12: NA | M12: Matriz_Actividades-Tareas_AyB.xlsx | N12: BAJA | O12: ANA MARÍA ACEVEDO | P12: anamaria.acevedo@araybustamante.cl | Q12: anamaria.acevedo@araybustamante.cl | R12: carlos.arag@araybustamante.cl | S12: * CARTOLAS BANCARIAS * CARTOLAS DE INVERSIÓN * LIBRO BANCO * FACTURAS (COMPRAS Y VENTAS DE INVERSIONES) * OPCIONALES: CONTRATOS DE ARRIENDOS, PAGARÉS, ENTRE OTROS | T12: * FORMULARIO 29 * AVISO DE PATENTES COMERCIALES (SEMESTRAL) * FORMULARIO 22 (PERSONA) * FORMULARIO 22 | U12: 45869
A13: 1 | B13: GRUPO ABCIA | C13: 12 | D13: LA LLAVERIA INTERNACIONAL SPA | E13: LA LLAVERÍA INTERNACIONAL | F13: 78036542-0 | G13: =D13 -> LA LLAVERIA INTERNACIONAL SPA | H13: =COUNTIFS(RELACIONADAS!$C:$C,CLIENTES!$F13,RELACIONADAS!$G:$G,"SI") -> 2 | I13: =COUNTIFS(RELACIONADAS!$C:$C,CLIENTES!$F13,RELACIONADAS!$H:$H,"SI") -> 1 | J13: CONTABLE | K13: PERMANENTE | L13: NA | M13: Matriz_Actividades-Tareas_AyB.xlsx | N13: BAJA | O13: ANA MARÍA ACEVEDO | P13: anamaria.acevedo@araybustamante.cl | Q13: anamaria.acevedo@araybustamante.cl | R13: carlos.arag@araybustamante.cl | S13: * CARTOLAS BANCARIAS * CARTOLAS DE INVERSIÓN * LIBRO BANCO * FACTURAS (COMPRAS Y VENTAS DE INVERSIONES) * OPCIONALES: CONTRATOS DE ARRIENDOS, PAGARÉS, ENTRE OTROS | T13: * FORMULARIO 29 * AVISO DE PATENTES COMERCIALES (SEMESTRAL) * FORMULARIO 22 (PERSONA) * FORMULARIO 22 | U13: 45869
... A101: 21 | B101: GRUPO GILABERT | C101: 1 | D101: VITT SPA | E101: VITT | F101: 78884090-K | G101: =D101 -> VITT SPA | H101: =COUNTIFS(RELACIONADAS!$C:$C,CLIENTES!$F101,RELACIONADAS!$G:$G,"SI") -> 2 | I101: =COUNTIFS(RELACIONADAS!$C:$C,CLIENTES!$F101,RELACIONADAS!$H:$H,"SI") -> 2 | J101: TRIBUTARIO | K101: ANUAL | L101: NA | M101: Matriz_Actividades-Tareas_AyB.xlsx | N101: ALTA | O101: CARLOS ARA | P101: anamaria.acevedo@araybustamante.cl | Q101: anamaria.acevedo@araybustamante.cl | R101: carlos.arag@araybustamante.cl | S101: * BALANCE GENERAL * LIBRO MAYOR CARTOLAS DE INVERSIONES * INFORME DE PRINCIPALES CUENTAS CONTABLES | T101: * CERTIFICADO DE PRESENTACIÓN DE RENTA | U101: 45869
A102: 21 | B102: GRUPO GILABERT | C102: =C101+1 -> 2 | D102: INVERSIONES BLANQUITA SPA | E102: BLANQUITA | F102: 76092514-4 | G102: =D102 -> INVERSIONES BLANQUITA SPA | H102: =COUNTIFS(RELACIONADAS!$C:$C,CLIENTES!$F102,RELACIONADAS!$G:$G,"SI") -> 2 | I102: =COUNTIFS(RELACIONADAS!$C:$C,CLIENTES!$F102,RELACIONADAS!$H:$H,"SI") -> 2 | J102: TRIBUTARIO | K102: ANUAL | L102: NA | M102: Matriz_Actividades-Tareas_AyB.xlsx | N102: ALTA | O102: CARLOS ARA | P102: anamaria.acevedo@araybustamante.cl | Q102: anamaria.acevedo@araybustamante.cl | R102: carlos.arag@araybustamante.cl | S102: * BALANCE GENERAL * LIBRO MAYOR CARTOLAS DE INVERSIONES * INFORME DE PRINCIPALES CUENTAS CONTABLES | T102: * CERTIFICADO DE PRESENTACIÓN DE RENTA | U102: 45869
A103: 21 | B103: GRUPO GILABERT | C103: =C102+1 -> 3 | D103: URBAN DEVELOPMENT ASESORIAS LIMITADA | E103: URBAN | F103: 76195220-K | G103: =D103 -> URBAN DEVELOPMENT ASESORIAS LIMITADA | H103: =COUNTIFS(RELACIONADAS!$C:$C,CLIENTES!$F103,RELACIONADAS!$G:$G,"SI") -> 2 | I103: =COUNTIFS(RELACIONADAS!$C:$C,CLIENTES!$F103,RELACIONADAS!$H:$H,"SI") -> 2 | J103: TRIBUTARIO | K103: ANUAL | L103: NA | M103: Matriz_Actividades-Tareas_AyB.xlsx | N103: ALTA | O103: CARLOS ARA | P103: anamaria.acevedo@araybustamante.cl | Q103: anamaria.acevedo@araybustamante.cl | R103: carlos.arag@araybustamante.cl | S103: * BALANCE GENERAL * LIBRO MAYOR CARTOLAS DE INVERSIONES * INFORME DE PRINCIPALES CUENTAS CONTABLES | T103: * CERTIFICADO DE PRESENTACIÓN DE RENTA | U103: 45869
A104: 21 | B104: GRUPO GILABERT | C104: =C103+1 -> 4 | D104: INMOBILIARIA ANGUSMAR SPA | E104: ANGUSMAR | F104: 76091928-4 | G104: =D104 -> INMOBILIARIA ANGUSMAR SPA | H104: =COUNTIFS(RELACIONADAS!$C:$C,CLIENTES!$F104,RELACIONADAS!$G:$G,"SI") -> 2 | I104: =COUNTIFS(RELACIONADAS!$C:$C,CLIENTES!$F104,RELACIONADAS!$H:$H,"SI") -> 8 | J104: TRIBUTARIO | K104: ANUAL | L104: NA | M104: Matriz_Actividades-Tareas_AyB.xlsx | N104: ALTA | O104: CARLOS ARA | P104: anamaria.acevedo@araybustamante.cl | Q104: anamaria.acevedo@araybustamante.cl | R104: carlos.arag@araybustamante.cl | S104: * BALANCE GENERAL * LIBRO MAYOR CARTOLAS DE INVERSIONES * INFORME DE PRINCIPALES CUENTAS CONTABLES | T104: * CERTIFICADO DE PRESENTACIÓN DE RENTA | U104: 45869
A105: 21 | B105: GRUPO GILABERT | C105: =C104+1 -> 5 | D105: INMOBILIARIA SOLINGEN SPA | E105: SOLINGEN | F105: 76392095-K | G105: =D105 -> INMOBILIARIA SOLINGEN SPA | H105: =COUNTIFS(RELACIONADAS!$C:$C,CLIENTES!$F105,RELACIONADAS!$G:$G,"SI") -> 2 | I105: =COUNTIFS(RELACIONADAS!$C:$C,CLIENTES!$F105,RELACIONADAS!$H:$H,"SI") -> 16 | J105: TRIBUTARIO | K105: ANUAL | L105: NA | M105: Matriz_Actividades-Tareas_AyB.xlsx | N105: ALTA | O105: CARLOS ARA | P105: anamaria.acevedo@araybustamante.cl | Q105: anamaria.acevedo@araybustamante.cl | R105: carlos.arag@araybustamante.cl | S105: * BALANCE GENERAL * LIBRO MAYOR CARTOLAS DE INVERSIONES * INFORME DE PRINCIPALES CUENTAS CONTABLES | T105: * CERTIFICADO DE PRESENTACIÓN DE RENTA | U105: 45869
A106: 21 | B106: GRUPO GILABERT | C106: =C105+1 -> 6 | D106: MONICA SAHR C Y COMPANIA LIMITADA | E106: TAGUA | F106: 77397050-5 | G106: =D106 -> MONICA SAHR C Y COMPANIA LIMITADA | H106: =COUNTIFS(RELACIONADAS!$C:$C,CLIENTES!$F106,RELACIONADAS!$G:$G,"SI") -> 2 | I106: =COUNTIFS(RELACIONADAS!$C:$C,CLIENTES!$F106,RELACIONADAS!$H:$H,"SI") -> 2 | J106: TRIBUTARIO | K106: ANUAL | L106: NA | M106: Matriz_Actividades-Tareas_AyB.xlsx | N106: ALTA | O106: CARLOS ARA | P106: anamaria.acevedo@araybustamante.cl | Q106: anamaria.acevedo@araybustamante.cl | R106: carlos.arag@araybustamante.cl | S106: * BALANCE GENERAL * LIBRO MAYOR CARTOLAS DE INVERSIONES * INFORME DE PRINCIPALES CUENTAS CONTABLES | T106: * CERTIFICADO DE PRESENTACIÓN DE RENTA | U106: 45869
A107: 21 | B107: GRUPO GILABERT | C107: =C106+1 -> 7 | D107: INVERSIONES MACDONALD FORD LIMITADA | E107: IMAC | F107: 76000881-8 | G107: =D107 -> INVERSIONES MACDONALD FORD LIMITADA | H107: =COUNTIFS(RELACIONADAS!$C:$C,CLIENTES!$F107,RELACIONADAS!$G:$G,"SI") -> 2 | I107: =COUNTIFS(RELACIONADAS!$C:$C,CLIENTES!$F107,RELACIONADAS!$H:$H,"SI") -> 2 | J107: TRIBUTARIO | K107: ANUAL | L107: NA | M107: Matriz_Actividades-Tareas_AyB.xlsx | N107: ALTA | O107: CARLOS ARA | P107: anamaria.acevedo@araybustamante.cl | Q107: anamaria.acevedo@araybustamante.cl | R107: carlos.arag@araybustamante.cl | S107: * BALANCE GENERAL * LIBRO MAYOR CARTOLAS DE INVERSIONES * INFORME DE PRINCIPALES CUENTAS CONTABLES | T107: * CERTIFICADO DE PRESENTACIÓN DE RENTA | U107: 45869
A108: 21 | B108: GRUPO GILABERT | C108: =C107+1 -> 8 | D108: COMERCIALIZADORA SIMPLETECH LIMITADA | E108: SIMPLETECH | F108: 76817979-4 | G108: =D108 -> COMERCIALIZADORA SIMPLETECH LIMITADA | H108: =COUNTIFS(RELACIONADAS!$C:$C,CLIENTES!$F108,RELACIONADAS!$G:$G,"SI") -> 1 | I108: =COUNTIFS(RELACIONADAS!$C:$C,CLIENTES!$F108,RELACIONADAS!$H:$H,"SI") -> 2 | J108: TRIBUTARIO | K108: ANUAL | L108: NA | M108: Matriz_Actividades-Tareas_AyB.xlsx | N108: ALTA | O108: CARLOS ARA | P108: anamaria.acevedo@araybustamante.cl | Q108: anamaria.acevedo@araybustamante.cl | R108: carlos.arag@araybustamante.cl | S108: * BALANCE GENERAL * LIBRO MAYOR CARTOLAS DE INVERSIONES * INFORME DE PRINCIPALES CUENTAS CONTABLES | T108: * CERTIFICADO DE PRESENTACIÓN DE RENTA | U108: 45869
A109: 21 | B109: GRUPO GILABERT | C109: =C108+1 -> 9 | D109: SUBCENTRO LAS CONDES SA | E109: LAS CONDES | F109: 99567710-5 | G109: =D109 -> SUBCENTRO LAS CONDES SA | H109: =COUNTIFS(RELACIONADAS!$C:$C,CLIENTES!$F109,RELACIONADAS!$G:$G,"SI") -> 1 | I109: =COUNTIFS(RELACIONADAS!$C:$C,CLIENTES!$F109,RELACIONADAS!$H:$H,"SI") -> 9 | J109: TRIBUTARIO | K109: ANUAL | L109: NA | M109: Matriz_Actividades-Tareas_AyB.xlsx | N109: ALTA | O109: CARLOS ARA | P109: anamaria.acevedo@araybustamante.cl | Q109: anamaria.acevedo@araybustamante.cl | R109: carlos.arag@araybustamante.cl | S109: * BALANCE GENERAL * LIBRO MAYOR CARTOLAS DE INVERSIONES * INFORME DE PRINCIPALES CUENTAS CONTABLES | T109: * CERTIFICADO DE PRESENTACIÓN DE RENTA | U109: 45869
A110: 22 | B110: GRUPO AGRICOLAS | C110: 1 | D110: AGRICOLA COVADONGA LIMITADA | E110: AGRICOLA COVADONGA | F110: 77194550-3 | G110: =D110 -> AGRICOLA COVADONGA LIMITADA | H110: =COUNTIFS(RELACIONADAS!$C:$C,CLIENTES!$F110,RELACIONADAS!$G:$G,"SI") -> 1 | I110: =COUNTIFS(RELACIONADAS!$C:$C,CLIENTES!$F110,RELACIONADAS!$H:$H,"SI") -> 2 | J110: TRIBUTARIO | K110: ANUAL | L110: NA | M110: Matriz_Actividades-Tareas_AyB.xlsx | N110: ALTA | O110: CARLOS ARA | P110: anamaria.acevedo@araybustamante.cl | Q110: anamaria.acevedo@araybustamante.cl | R110: carlos.arag@araybustamante.cl | S110: * BALANCE GENERAL * LIBRO MAYOR CARTOLAS DE INVERSIONES * INFORME DE PRINCIPALES CUENTAS CONTABLES | T110: * CERTIFICADO DE PRESENTACIÓN DE RENTA | U110: 45869
A111: 22 | B111: GRUPO AGRICOLAS | C111: 2 | D111: SOC AGRICOLA EL CARMEN DE PUCALAN LIMITADA | E111: AGRICOLA EL CARMEN | F111: 79747860-1 | G111: =D111 -> SOC AGRICOLA EL CARMEN DE PUCALAN LIMITADA | H111: =COUNTIFS(RELACIONADAS!$C:$C,CLIENTES!$F111,RELACIONADAS!$G:$G,"SI") -> 1 | I111: =COUNTIFS(RELACIONADAS!$C:$C,CLIENTES!$F111,RELACIONADAS!$H:$H,"SI") -> 2 | J111: TRIBUTARIO | K111: ANUAL | L111: NA | M111: Matriz_Actividades-Tareas_AyB.xlsx | N111: ALTA | O111: CARLOS ARA | P111: anamaria.acevedo@araybustamante.cl | Q111: anamaria.acevedo@araybustamante.cl | R111: carlos.arag@araybustamante.cl | S111: * BALANCE GENERAL * LIBRO MAYOR CARTOLAS DE INVERSIONES * INFORME DE PRINCIPALES CUENTAS CONTABLES | T111: * CERTIFICADO DE PRESENTACIÓN DE RENTA | U111: 45869
A112: 22 | B112: GRUPO AGRICOLAS | C112: 3 | D112: AGRICOLA LOMAS DE MAITENES LIMITADA | E112: AGRICOLA LOMAS | F112: 77013780-2 | G112: =D112 -> AGRICOLA LOMAS DE MAITENES LIMITADA | H112: =COUNTIFS(RELACIONADAS!$C:$C,CLIENTES!$F112,RELACIONADAS!$G:$G,"SI") -> 4 | I112: =COUNTIFS(RELACIONADAS!$C:$C,CLIENTES!$F112,RELACIONADAS!$H:$H,"SI") -> 3 | J112: TRIBUTARIO | K112: ANUAL | L112: NA | M112: Matriz_Actividades-Tareas_AyB.xlsx | N112: ALTA | O112: CARLOS ARA | P112: anamaria.acevedo@araybustamante.cl | Q112: anamaria.acevedo@araybustamante.cl | R112: carlos.arag@araybustamante.cl | S112: * BALANCE GENERAL * LIBRO MAYOR CARTOLAS DE INVERSIONES * INFORME DE PRINCIPALES CUENTAS CONTABLES | T112: * CERTIFICADO DE PRESENTACIÓN DE RENTA | U112: 45869
A113: 22 | B113: GRUPO AGRICOLAS | C113: 4 | D113: ADMINISTRADORA DON FERNANDO LIMITADA | E113: DON FERNANDO | F113: 78139980-9 | G113: =D113 -> ADMINISTRADORA DON FERNANDO LIMITADA | H113: =COUNTIFS(RELACIONADAS!$C:$C,CLIENTES!$F113,RELACIONADAS!$G:$G,"SI") -> 1 | I113: =COUNTIFS(RELACIONADAS!$C:$C,CLIENTES!$F113,RELACIONADAS!$H:$H,"SI") -> 2 | J113: TRIBUTARIO | K113: ANUAL | L113: NA | M113: Matriz_Actividades-Tareas_AyB.xlsx | N113: ALTA | O113: CARLOS ARA | P113: anamaria.acevedo@araybustamante.cl | Q113: anamaria.acevedo@araybustamante.cl | R113: carlos.arag@araybustamante.cl | S113: * BALANCE GENERAL * LIBRO MAYOR CARTOLAS DE INVERSIONES * INFORME DE PRINCIPALES CUENTAS CONTABLES | T113: * CERTIFICADO DE PRESENTACIÓN DE RENTA | U113: 45869
A114: 23 | B114: GRUPO USACH | C114: 1 | D114: SOC DE DESARROLLO TECNOLÓGICO DE LA USACH LTDA | E114: DESARROLLO USACH | F114: 78172420-3 | G114: =D114 -> SOC DE DESARROLLO TECNOLÓGICO DE LA USACH LTDA | H114: =COUNTIFS(RELACIONADAS!$C:$C,CLIENTES!$F114,RELACIONADAS!$G:$G,"SI") -> 1 | I114: =COUNTIFS(RELACIONADAS!$C:$C,CLIENTES!$F114,RELACIONADAS!$H:$H,"SI") -> 2 | J114: TRIBUTARIO | K114: ANUAL | L114: NA | M114: Matriz_Actividades-Tareas_AyB.xlsx | N114: ALTA | O114: CARLOS ARA | P114: anamaria.acevedo@araybustamante.cl | Q114: anamaria.acevedo@araybustamante.cl | R114: carlos.arag@araybustamante.cl | S114: * BALANCE GENERAL * LIBRO MAYOR CARTOLAS DE INVERSIONES * INFORME DE PRINCIPALES CUENTAS CONTABLES | T114: * CERTIFICADO DE PRESENTACIÓN DE RENTA | U114: 45869
A115: 23 | B115: GRUPO USACH | C115: 2 | D115: CAPACITACIÓN USACH CIA LTDA | E115: CAPACITACIÓN USACH | F115: 76421320-3 | G115: =D115 -> CAPACITACIÓN USACH CIA LTDA | H115: =COUNTIFS(RELACIONADAS!$C:$C,CLIENTES!$F115,RELACIONADAS!$G:$G,"SI") -> 1 | I115: =COUNTIFS(RELACIONADAS!$C:$C,CLIENTES!$F115,RELACIONADAS!$H:$H,"SI") -> 2 | J115: TRIBUTARIO | K115: ANUAL | L115: NA | M115: Matriz_Actividades-Tareas_AyB.xlsx | N115: ALTA | O115: CARLOS ARA | P115: anamaria.acevedo@araybustamante.cl | Q115: anamaria.acevedo@araybustamante.cl | R115: carlos.arag@araybustamante.cl | S115: * BALANCE GENERAL * LIBRO MAYOR CARTOLAS DE INVERSIONES * INFORME DE PRINCIPALES CUENTAS CONTABLES | T115: * CERTIFICADO DE PRESENTACIÓN DE RENTA | U115: 45869
A116: 23 | B116: GRUPO USACH | C116: 3 | D116: FUNDACIÓN PARA EL DESARROLLO DEL EMPRENDIMIENTO | E116: EMPRENDIMIENTO USACH | F116: 72499400-8 | G116: =D116 -> FUNDACIÓN PARA EL DESARROLLO DEL EMPRENDIMIENTO | H116: =COUNTIFS(RELACIONADAS!$C:$C,CLIENTES!$F116,RELACIONADAS!$G:$G,"SI") -> 1 | I116: =COUNTIFS(RELACIONADAS!$C:$C,CLIENTES!$F116,RELACIONADAS!$H:$H,"SI") -> 1 | J116: TRIBUTARIO | K116: ANUAL | L116: NA | M116: Matriz_Actividades-Tareas_AyB.xlsx | N116: ALTA | O116: CARLOS ARA | P116: anamaria.acevedo@araybustamante.cl | Q116: anamaria.acevedo@araybustamante.cl | R116: carlos.arag@araybustamante.cl | S116: * BALANCE GENERAL * LIBRO MAYOR CARTOLAS DE INVERSIONES * INFORME DE PRINCIPALES CUENTAS CONTABLES | T116: * CERTIFICADO DE PRESENTACIÓN DE RENTA | U116: 45869
A117: 23 | B117: GRUPO USACH | C117: 4 | D117: AG CERTIFICADORA DE COMPETENCIAS DE LA USACH LTDA | E117: COMPETENCIAS USACH | F117: 76320355-7 | G117: =D117 -> AG CERTIFICADORA DE COMPETENCIAS DE LA USACH LTDA | H117: =COUNTIFS(RELACIONADAS!$C:$C,CLIENTES!$F117,RELACIONADAS!$G:$G,"SI") -> 1 | I117: =COUNTIFS(RELACIONADAS!$C:$C,CLIENTES!$F117,RELACIONADAS!$H:$H,"SI") -> 2 | J117: TRIBUTARIO | K117: ANUAL | L117: NA | M117: Matriz_Actividades-Tareas_AyB.xlsx | N117: ALTA | O117: CARLOS ARA | P117: anamaria.acevedo@araybustamante.cl | Q117: anamaria.acevedo@araybustamante.cl | R117: carlos.arag@araybustamante.cl | S117: * BALANCE GENERAL * LIBRO MAYOR CARTOLAS DE INVERSIONES * INFORME DE PRINCIPALES CUENTAS CONTABLES | T117: * CERTIFICADO DE PRESENTACIÓN DE RENTA | U117: 45869
A118: 23 | B118: GRUPO USACH | C118: 5 | D118: FUNDACIÓN UNIVERSITARIA ESCUELA DE OFICIOS USACH | E118: OFICIOS USACH | F118: 65081063-5 | G118: =D118 -> FUNDACIÓN UNIVERSITARIA ESCUELA DE OFICIOS USACH | H118: =COUNTIFS(RELACIONADAS!$C:$C,CLIENTES!$F118,RELACIONADAS!$G:$G,"SI") -> 1 | I118: =COUNTIFS(RELACIONADAS!$C:$C,CLIENTES!$F118,RELACIONADAS!$H:$H,"SI") -> 0 | J118: TRIBUTARIO | K118: ANUAL | L118: NA | M118: Matriz_Actividades-Tareas_AyB.xlsx | N118: ALTA | O118: CARLOS ARA | P118: anamaria.acevedo@araybustamante.cl | Q118: anamaria.acevedo@araybustamante.cl | R118: carlos.arag@araybustamante.cl | S118: * BALANCE GENERAL * LIBRO MAYOR CARTOLAS DE INVERSIONES * INFORME DE PRINCIPALES CUENTAS CONTABLES | T118: * CERTIFICADO DE PRESENTACIÓN DE RENTA | U118: 45869
A119: 24 | B119: GRUPO GONZALO | C119: 1 | D119: INVERSIONES VALLE ORIENTE LIMITADA | E119: VALLE ORIENTE | F119: 76038017-2 | G119: =D119 -> INVERSIONES VALLE ORIENTE LIMITADA | H119: =COUNTIFS(RELACIONADAS!$C:$C,CLIENTES!$F119,RELACIONADAS!$G:$G,"SI") -> 3 | I119: =COUNTIFS(RELACIONADAS!$C:$C,CLIENTES!$F119,RELACIONADAS!$H:$H,"SI") -> 2 | J119: TRIBUTARIO | K119: ANUAL | L119: NA | M119: Matriz_Actividades-Tareas_AyB.xlsx | N119: ALTA | O119: CARLOS ARA | P119: anamaria.acevedo@araybustamante.cl | Q119: anamaria.acevedo@araybustamante.cl | R119: carlos.arag@araybustamante.cl | S119: * BALANCE GENERAL * LIBRO MAYOR CARTOLAS DE INVERSIONES * INFORME DE PRINCIPALES CUENTAS CONTABLES | T119: * CERTIFICADO DE PRESENTACIÓN DE RENTA | U119: 45869
A120: 24 | B120: GRUPO GONZALO | C120: 2 | D120: INVERSIONES ICABARU SA | E120: ICABARU | F120: 91366000-5 | G120: =D120 -> INVERSIONES ICABARU SA | H120: =COUNTIFS(RELACIONADAS!$C:$C,CLIENTES!$F120,RELACIONADAS!$G:$G,"SI") -> 1 | I120: =COUNTIFS(RELACIONADAS!$C:$C,CLIENTES!$F120,RELACIONADAS!$H:$H,"SI") -> 4 | J120: TRIBUTARIO | K120: ANUAL | L120: NA | M120: Matriz_Actividades-Tareas_AyB.xlsx | N120: ALTA | O120: CARLOS ARA | P120: anamaria.acevedo@araybustamante.cl | Q120: anamaria.acevedo@araybustamante.cl | R120: carlos.arag@araybustamante.cl | S120: * BALANCE GENERAL * LIBRO MAYOR CARTOLAS DE INVERSIONES * INFORME DE PRINCIPALES CUENTAS CONTABLES | T120: * CERTIFICADO DE PRESENTACIÓN DE RENTA | U120: 45869
A121: 24 | B121: GRUPO GONZALO | C121: 3 | D121: ASESORIAS E INVERSIONES MANCORA LIMITADA | E121: MANCORA | F121: 76278370-3 | G121: =D121 -> ASESORIAS E INVERSIONES MANCORA LIMITADA | H121: =COUNTIFS(RELACIONADAS!$C:$C,CLIENTES!$F121,RELACIONADAS!$G:$G,"SI") -> 1 | I121: =COUNTIFS(RELACIONADAS!$C:$C,CLIENTES!$F121,RELACIONADAS!$H:$H,"SI") -> 7 | J121: TRIBUTARIO | K121: ANUAL | L121: NA | M121: Matriz_Actividades-Tareas_AyB.xlsx | N121: ALTA | O121: CARLOS ARA | P121: anamaria.acevedo@araybustamante.cl | Q121: anamaria.acevedo@araybustamante.cl | R121: carlos.arag@araybustamante.cl | S121: * BALANCE GENERAL * LIBRO MAYOR CARTOLAS DE INVERSIONES * INFORME DE PRINCIPALES CUENTAS CONTABLES | T121: * CERTIFICADO DE PRESENTACIÓN DE RENTA | U121: 45869
... A132: 25 | B132: GRUPO COX | C132: 5 | D132: EMPRESA COX INGENIEROS SA | E132: COX INGENIEROS | F132: 99563280-2 | G132: =D132 -> EMPRESA COX INGENIEROS SA | H132: =COUNTIFS(RELACIONADAS!$C:$C,CLIENTES!$F132,RELACIONADAS!$G:$G,"SI") -> 1 | I132: =COUNTIFS(RELACIONADAS!$C:$C,CLIENTES!$F132,RELACIONADAS!$H:$H,"SI") -> 2 | J132: TRIBUTARIO | K132: ANUAL | L132: NA | M132: Matriz_Actividades-Tareas_AyB.xlsx | N132: ALTA | O132: CARLOS ARA | P132: anamaria.acevedo@araybustamante.cl | Q132: anamaria.acevedo@araybustamante.cl | R132: carlos.arag@araybustamante.cl | S132: * BALANCE GENERAL * LIBRO MAYOR CARTOLAS DE INVERSIONES * INFORME DE PRINCIPALES CUENTAS CONTABLES | T132: * CERTIFICADO DE PRESENTACIÓN DE RENTA | U132: 45869

Sheet RELACIONADAS
A1: GRUPO | B1: EMPRESA | C1: RUT EMPRESA | D1: TIPO RELACIONADO | E1: NOMBRE RELACIONADO | F1: RUT RELACIONADO | G1: REPRESENTANTE LEGAL | H1: SOCIO | I1: % PARTICIPACIÓN SOCIO
A2: GRUPO ABCIA | B2: RENTAS LEXCORP LIMITADA | C2: 78952550-1 | D2: PERSONA NATURAL | E2: FRANCISCO JAVIER ALLENDE DECOMBE | F2: 7032531-4 | G2: SI | H2: NO
A3: GRUPO ABCIA | B3: RENTAS LEXCORP LIMITADA | C3: 78952550-1 | D3: PERSONA JURIDICA | E3: RENTAS LA LLAVERIA LIMITADA | F3: 76007540-k | G3: NO | H3: SI | I3: 0.4448
A4: GRUPO ABCIA | B4: RENTAS LEXCORP LIMITADA | C4: 78952550-1 | D4: PERSONA JURIDICA | E4: SOCIEDAS CIVIL DE RENTAS LA PASTORA S.C | F4: 76082746-0 | G4: NO | H4: SI | I4: 0.1104
A5: GRUPO ABCIA | B5: RENTAS LEXCORP LIMITADA | C5: 78952550-1 | D5: PERSONA JURIDICA | E5: INVERSIONES RODAS DE BAHIA LIMITADA | F5: 79978870-5 | G5: NO | H5: SI | I5: 0.4448
A6: GRUPO ABCIA | B6: SOCIEDAS CIVIL DE RENTAS LA PASTORA S.C | C6: 76082746-0 | D6: PERSONA NATURAL | E6: FELIPE ALBERTO ALLENDE DECOMBE | F6: 7032527-6 | G6: SI | H6: NO
A7: GRUPO ABCIA | B7: SOCIEDAS CIVIL DE RENTAS LA PASTORA S.C | C7: 76082746-0 | D7: PERSONA NATURAL | E7: FRANCISCO JAVIER ALLENDE DECOMBE | F7: 7032531-4 | G7: SI | H7: NO
A8: GRUPO ABCIA | B8: SOCIEDAS CIVIL DE RENTAS LA PASTORA S.C | C8: 76082746-0 | D8: PERSONA JURIDICA | E8: SOCIEDAD CIVIL DE RENTAS CADINI | F8: 76082218-3 | G8: NO | H8: SI | I8: 0.1087
A9: GRUPO ABCIA | B9: SOCIEDAS CIVIL DE RENTAS LA PASTORA S.C | C9: 76082746-0 | D9: PERSONA JURIDICA | E9: SOCIEDAD CIVIL RENTAS IGNACIO | F9: 76082741-K | G9: NO | H9: SI | I9: 0.1087
A10: GRUPO ABCIA | B10: SOCIEDAS CIVIL DE RENTAS LA PASTORA S.C | C10: 76082746-0 | D10: PERSONA JURIDICA | E10: RENTAS E INVERSIONES MONTREAL LIMITADA | F10: 76452272-9 | G10: NO | H10: SI | I10: 0.1087
A11: GRUPO ABCIA | B11: SOCIEDAS CIVIL DE RENTAS LA PASTORA S.C | C11: 76082746-0 | D11: PERSONA JURIDICA | E11: ASESORIAS E INVERSIONES SANTA ELOISA SPA. | F11: 77542465-6 | G11: NO | H11: SI | I11: 0.1087
A12: GRUPO ABCIA | B12: SOCIEDAS CIVIL DE RENTAS LA PASTORA S.C | C12: 76082746-0 | D12: PERSONA JURIDICA | E12: INVERSIONES SMITHFIELD LIMITADA | F12: 77550165-0 | G12: NO | H12: SI | I12: 0.1087
A13: GRUPO ABCIA | B13: SOCIEDAS CIVIL DE RENTAS LA PASTORA S.C | C13: 76082746-0 | D13: PERSONA JURIDICA | E13: RENTAS LEXCORP LIMITADA | F13: 78952550-1 | G13: NO | H13: SI | I13: 0.4565
A14: GRUPO ABCIA | B14: INVERSIONES RODAS DE BAHIA LIMITADA | C14: 79978870-5 | D14: PERSONA NATURAL | E14: FRANCISCO JAVIER ALLENDE DECOMBE | F14: 7032531-4 | G14: SI | H14: NO
A15: GRUPO ABCIA | B15: INVERSIONES RODAS DE BAHIA LIMITADA | C15: 79978870-5 | D15: PERSONA NATURAL | E15: FRANCISCO JAVIER ALLENDE PEREZ DE ARCE | F15: 16663359-1 | G15: NO | H15: SI | I15: 0.0001
A16: GRUPO ABCIA | B16: INVERSIONES RODAS DE BAHIA LIMITADA | C16: 79978870-5 | D16: PERSONA NATURAL | E16: JOSÉ ALBERTO ALLENDE PERÉZ DE ARCE | F16: 17268789-K | G16: NO | H16: SI | I16: 6.6666667e-05
A17: GRUPO ABCIA | B17: INVERSIONES RODAS DE BAHIA LIMITADA | C17: 79978870-5 | D17: PERSONA NATURAL | E17: VICENTE ALLENDE PEREZ DE ARCE | F17: 17700022-1 | G17: NO | H17: SI | I17: 6.6666667e-05
A18: GRUPO ABCIA | B18: INVERSIONES RODAS DE BAHIA LIMITADA | C18: 79978870-5 | D18: PERSONA NATURAL | E18: MARIA ELENA ALLENDE PEREZ DE ARCE | F18: 18934109-1 | G18: NO | H18: SI | I18: 6.6666667e-05
A19: GRUPO ABCIA | B19: INVERSIONES RODAS DE BAHIA LIMITADA | C19: 79978870-5 | D19: PERSONA NATURAL | E19: ANDRES ALLENDE PEREZ DE ARCE | F19: 19246955-4 | G19: NO | H19: SI | I19: 6.6666667e-05
A20: GRUPO ABCIA | B20: INVERSIONES RODAS DE BAHIA LIMITADA | C20: 79978870-5 | D20: PERSONA NATURAL | E20: MARIA GRACIA ALLENDE PEREZ DE ARCE | F20: 20444507-9 | G20: NO | H20: SI | I20: 6.6666667e-05
A21: GRUPO ABCIA | B21: INVERSIONES RODAS DE BAHIA LIMITADA | C21: 79978870-5 | D21: PERSONA NATURAL | E21: CRISTOBAL ALLENDE PEREZ DE ARCE | F21: 21551467-6 | G21: NO | H21: SI | I21: 6.6666667e-05
A22: GRUPO ABCIA | B22: INVERSIONES RODAS DE BAHIA LIMITADA | C22: 79978870-5 | D22: PERSONA JURIDICA | E22: SOCIEDAD CIVIL DE RENTAS CADINI | F22: 76082218-3 | G22: NO | H22: SI | I22: 0.9996
A23: GRUPO ABCIA | B23: RENTAS LA LLAVERIA LIMITADA | C23: 76007540-k | D23: PERSONA NATURAL | E23: LUZ MARIA ALLIENDE GONZALEZ | F23: 10723584-1 | G23: SI | H23: NO
A24: GRUPO ABCIA | B24: RENTAS LA LLAVERIA LIMITADA | C24: 76007540-k | D24: PERSONA NATURAL | E24: FELIPE ALBERTO ALLENDE DECOMBE | F24: 7032527-6 | G24: SI | H24: SI | I24: 0.25
A25: GRUPO ABCIA | B25: RENTAS LA LLAVERIA LIMITADA | C25: 76007540-k | D25: PERSONA JURIDICA | E25: SOCIEDAD CIVIL DE RENTAS EL ARCON | F25: 77989350-2 | G25: NO | H25: SI | I25: 0.75
A26: GRUPO ABCIA | B26: RENTAS ALPER LIMITADA | C26: 53317631-3 | D26: PERSONA NATURAL | E26: FRANCISCO JAVIER ALLENDE DECOMBE | F26: 7032531-4 | G26: SI | H26: NO
A27: GRUPO ABCIA | B27: RENTAS ALPER LIMITADA | C27: 53317631-3 | D27: PERSONA NATURAL | E27: MARIA ELENA PEREZ DE ARCE ARAYA | F27: 8930871-2 | G27: SI | H27: NO
A28: GRUPO ABCIA | B28: RENTAS ALPER LIMITADA | C28: 53317631-3 | D28: PERSONA NATURAL | E28: FRANCISCO JAVIER ALLENDE PEREZ DE ARCE | F28: 16663359-1 | G28: NO | H28: SI | I28: 0.14285714
A29: GRUPO ABCIA | B29: RENTAS ALPER LIMITADA | C29: 53317631-3 | D29: PERSONA NATURAL | E29: JOSÉ ALBERTO ALLENDE PERÉZ DE ARCE | F29: 17268789-K | G29: NO | H29: SI | I29: 0.14285714
A30: GRUPO ABCIA | B30: RENTAS ALPER LIMITADA | C30: 53317631-3 | D30: PERSONA NATURAL | E30: VICENTE ALLENDE PEREZ DE ARCE | F30: 17700022-1 | G30: NO | H30: SI | I30: 0.14285714
A31: GRUPO ABCIA | B31: RENTAS ALPER LIMITADA | C31: 53317631-3 | D31: PERSONA NATURAL | E31: MARIA ELENA ALLENDE PEREZ DE ARCE | F31: 18934109-1 | G31: NO | H31: SI | I31: 0.14285714
A32: GRUPO ABCIA | B32: RENTAS ALPER LIMITADA | C32: 53317631-3 | D32: PERSONA NATURAL | E32: ANDRES ALLENDE PEREZ DE ARCE | F32: 19246955-4 | G32: NO | H32: SI | I32: 0.14285714
A33: GRUPO ABCIA | B33: RENTAS ALPER LIMITADA | C33: 53317631-3 | D33: PERSONA NATURAL | E33: MARIA GRACIA ALLENDE PEREZ DE ARCE | F33: 20444507-9 | G33: NO | H33: SI | I33: 0.14285714
A34: GRUPO ABCIA | B34: RENTAS ALPER LIMITADA | C34: 53317631-3 | D34: PERSONA NATURAL | E34: CRISTOBAL ALLENDE PEREZ DE ARCE | F34: 21551467-6 | G34: NO | H34: SI | I34: 0.14285714
A35: GRUPO ABCIA | B35: SOCIEDAD CIVIL DE RENTAS EL ARCON S.C | C35: 77989350-2 | D35: PERSONA NATURAL | E35: LUZ MARIA ALLIENDE GONZALEZ | F35: 10723584-1 | G35: SI | H35: SI | I35: 0.33333333
A36: GRUPO ABCIA | B36: SOCIEDAD CIVIL DE RENTAS EL ARCON S.C | C36: 77989350-2 | D36: PERSONA NATURAL | E36: FELIPE JOSE ALLENDE ALLIENDE | F36: 21276943-6 | G36: NO | H36: SI | I36: 0.33333333
A37: GRUPO ABCIA | B37: SOCIEDAD CIVIL DE RENTAS EL ARCON S.C | C37: 77989350-2 | D37: PERSONA NATURAL | E37: ALFONSO JOSE ALLENDE ALLIENDE | F37: 22485630-K | G37: NO | H37: SI | I37: 0.33333333
A38: GRUPO ABCIA | B38: RENTAS E INVERSIONES MONTREAL LIMITADA | C38: 76452272-9 | D38: PERSONA NATURAL | E38: CAROLINA ADRIANA LETELIER CASTILLO | F38: 13472089-1 | G38: SI | H38: SI | I38: 0.5
A39: GRUPO ABCIA | B39: RENTAS E INVERSIONES MONTREAL LIMITADA | C39: 76452272-9 | D39: PERSONA NATURAL | E39: JOSE LUIS IBANEZ BAFALLUY | F39: 13670630-6 | G39: SI | H39: SI | I39: 0.5
... A44: GRUPO ABCIA | B44: SOCIEDAD CIVIL DE RENTAS CADINI S.C | C44: 76082218-3 | D44: PERSONA NATURAL | E44: NICOLAS JOSE LIRA ISENSEE | F44: 19244565-5 | G44: NO | H44: SI | I44: 0.2
...

Sheet PROPUESTA FORMULARIO
A1: FORMULARIO PERSONAS NATURALES QUE HAN RECIBO SERVICIOS EN AYB
A3: CAMPOS FORMULARIO | B3: DESCRIPCIÓN CAMPO | C3: OBLIGATORIEDAD
A4: NOMBRE | B4: LIBRE | C4: OBLIGATORIO
A5: RUT | B5: RUT SIN PUNTOS Y GUIÓN | C5: OBLIGATORIO
A6: FECHA NACIMIENTO | B6: FECHA DD/MM/AAAA | C6: OBLIGATORIO
A7: NACIONALIDAD | B7: LIBRE | C7: OBLIGATORIO
A8: TELÉFONO MOVIL | B8: INCLUIR +569 | C8: OBLIGATORIO
A9: DIRECCIÓN PARTICULAR | B9: LIBRE | C9: OPCIONAL
A10: CORREO ELECTRÓNICO TRABAJO | B10: LIBRE | C10: OBLIGATORIO
A11: CORREO ELECTRÓNICO PERSONAL | B11: LIBRE | C11: OPCIONAL
A12: PROFESIÓN | B12: LIBRE | C12: OPCIONAL
A13: FECHA INGRESO COMO CLIENTE | B13: LIBRE | C13: OPCIONAL
A14: N° BIENES RAICES PERSONALES | B14: CANTIDAD | C14: OBLIGATORIO
... A31: REGISTRA SOCIOS NO RESIDENTES | B31: LIBRE | C31: OBLIGATORIO
A33: NOTA: ESTE FORMULARIO SERÁ ENVIADO PARA LA BASE DE "RELACIONADAS" SOLO PARA PERSONAS NATURALES.

Sheet MATRICES
B2: 1) | C2: TIPO DE SERVICIO | D2: CONTABLE
D3: TRIBUTARIO
B5: 2) | C5: PERIODICIDAD DEL SERVICIO | D5: PERMANENTE
D6: EXTRAORDINARIO
B8: 3) | C8: COMPLEJIDAD DEL CLIENTE | D8: ALTA
D9: MEDIA
D10: BAJA
B12: 4) | C12: EJECUTIVO CONTABLE A CARGO | D12: ANA MARÍA ACEVEDO
D13: NATALY ZELADA
B15: 5) | C15: INFORMACIÓN A RECIBIR DESDE EL CLIENTE | D15: * CARTOLAS BANCARIAS * CARTOLAS DE INVERSIÓN * LIBRO BANCO * FACTURAS (COMPRAS Y VENTAS DE INVERSIONES) * OPCIONALES: CONTRATOS DE ARRIENDOS, PAGARÉS, ENTRE OTROS
D16: * BALANCE GENERAL * LIBRO MAYOR CARTOLAS DE INVERSIONES * INFORME DE PRINCIPALES CUENTAS CONTABLES
B21: 6) | C21: INFORMACIÓN A MANDAR AL CLIENTE | D21: * FORMULARIO 29 * AVISO DE PATENTES COMERCIALES (SEMESTRAL) * FORMULARIO 22 (PERSONA) * FORMULARIO 22
D22: * CERTIFICADO DE PRESENTACIÓN DE RENTA
